2023-10-14 14:19:59 [urllib3.connectionpool] WARNING: Retrying (Retry(total=2, connect=None, read=None, redirect=None, status=None)) after connection broken by 'NewConnectionError('<urllib3.connection.HTTPConnection object at 0x000001E43F53C8E0>: Failed to establish a new connection: [WinError 10061] 由于目标计算机积极拒绝，无法连接。')': /session/51b15dc02d7e822ea9c369ba90e23ae4/url
2023-10-14 14:20:03 [urllib3.connectionpool] WARNING: Retrying (Retry(total=1, connect=None, read=None, redirect=None, status=None)) after connection broken by 'NewConnectionError('<urllib3.connection.HTTPConnection object at 0x000001E43F5FBAF0>: Failed to establish a new connection: [WinError 10061] 由于目标计算机积极拒绝，无法连接。')': /session/51b15dc02d7e822ea9c369ba90e23ae4/url
2023-10-14 14:20:07 [urllib3.connectionpool] WARNING: Retrying (Retry(total=0, connect=None, read=None, redirect=None, status=None)) after connection broken by 'NewConnectionError('<urllib3.connection.HTTPConnection object at 0x000001E43F6055E0>: Failed to establish a new connection: [WinError 10061] 由于目标计算机积极拒绝，无法连接。')': /session/51b15dc02d7e822ea9c369ba90e23ae4/url
2023-10-14 14:20:11 [scrapy.core.scraper] ERROR: Error downloading <GET https://news.163.com/domestic/>
Traceback (most recent call last):
  File "C:\Users\bzz00\PycharmProjects\pythonProject\pythonProject1\venv\lib\site-packages\urllib3\connectionpool.py", line 714, in urlopen
    httplib_response = self._make_request(
  File "C:\Users\bzz00\PycharmProjects\pythonProject\pythonProject1\venv\lib\site-packages\urllib3\connectionpool.py", line 466, in _make_request
    six.raise_from(e, None)
  File "<string>", line 3, in raise_from
  File "C:\Users\bzz00\PycharmProjects\pythonProject\pythonProject1\venv\lib\site-packages\urllib3\connectionpool.py", line 461, in _make_request
    httplib_response = conn.getresponse()
  File "C:\python\lib\http\client.py", line 1345, in getresponse
    response.begin()
  File "C:\python\lib\http\client.py", line 307, in begin
    version, status, reason = self._read_status()
  File "C:\python\lib\http\client.py", line 268, in _read_status
    line = str(self.fp.readline(_MAXLINE + 1), "iso-8859-1")
  File "C:\python\lib\socket.py", line 704, in readinto
    return self._sock.recv_into(b)
ConnectionResetError: [WinError 10054] 远程主机强迫关闭了一个现有的连接。

During handling of the above exception, another exception occurred:

Traceback (most recent call last):
  File "C:\Users\bzz00\PycharmProjects\pythonProject\pythonProject1\venv\lib\site-packages\twisted\internet\defer.py", line 1697, in _inlineCallbacks
    result = context.run(gen.send, result)
  File "C:\Users\bzz00\PycharmProjects\pythonProject\pythonProject1\venv\lib\site-packages\scrapy\core\downloader\middleware.py", line 68, in process_response
    method(request=request, response=response, spider=spider)
  File "C:\Users\bzz00\PycharmProjects\pythonProject\spider\scrapy库\mySpider03\mySpider03\middlewares.py", line 102, in process_response
    browser.get(request.url)
  File "C:\Users\bzz00\PycharmProjects\pythonProject\pythonProject1\venv\lib\site-packages\selenium\webdriver\remote\webdriver.py", line 449, in get
    self.execute(Command.GET, {"url": url})
  File "C:\Users\bzz00\PycharmProjects\pythonProject\pythonProject1\venv\lib\site-packages\selenium\webdriver\remote\webdriver.py", line 438, in execute
    response = self.command_executor.execute(driver_command, params)
  File "C:\Users\bzz00\PycharmProjects\pythonProject\pythonProject1\venv\lib\site-packages\selenium\webdriver\remote\remote_connection.py", line 290, in execute
    return self._request(command_info[0], url, body=data)
  File "C:\Users\bzz00\PycharmProjects\pythonProject\pythonProject1\venv\lib\site-packages\selenium\webdriver\remote\remote_connection.py", line 311, in _request
    response = self._conn.request(method, url, body=body, headers=headers)
  File "C:\Users\bzz00\PycharmProjects\pythonProject\pythonProject1\venv\lib\site-packages\urllib3\request.py", line 78, in request
    return self.request_encode_body(
  File "C:\Users\bzz00\PycharmProjects\pythonProject\pythonProject1\venv\lib\site-packages\urllib3\request.py", line 170, in request_encode_body
    return self.urlopen(method, url, **extra_kw)
  File "C:\Users\bzz00\PycharmProjects\pythonProject\pythonProject1\venv\lib\site-packages\urllib3\poolmanager.py", line 376, in urlopen
    response = conn.urlopen(method, u.request_uri, **kw)
  File "C:\Users\bzz00\PycharmProjects\pythonProject\pythonProject1\venv\lib\site-packages\urllib3\connectionpool.py", line 798, in urlopen
    retries = retries.increment(
  File "C:\Users\bzz00\PycharmProjects\pythonProject\pythonProject1\venv\lib\site-packages\urllib3\util\retry.py", line 550, in increment
    raise six.reraise(type(error), error, _stacktrace)
  File "C:\Users\bzz00\PycharmProjects\pythonProject\pythonProject1\venv\lib\site-packages\urllib3\packages\six.py", line 769, in reraise
    raise value.with_traceback(tb)
  File "C:\Users\bzz00\PycharmProjects\pythonProject\pythonProject1\venv\lib\site-packages\urllib3\connectionpool.py", line 714, in urlopen
    httplib_response = self._make_request(
  File "C:\Users\bzz00\PycharmProjects\pythonProject\pythonProject1\venv\lib\site-packages\urllib3\connectionpool.py", line 466, in _make_request
    six.raise_from(e, None)
  File "<string>", line 3, in raise_from
  File "C:\Users\bzz00\PycharmProjects\pythonProject\pythonProject1\venv\lib\site-packages\urllib3\connectionpool.py", line 461, in _make_request
    httplib_response = conn.getresponse()
  File "C:\python\lib\http\client.py", line 1345, in getresponse
    response.begin()
  File "C:\python\lib\http\client.py", line 307, in begin
    version, status, reason = self._read_status()
  File "C:\python\lib\http\client.py", line 268, in _read_status
    line = str(self.fp.readline(_MAXLINE + 1), "iso-8859-1")
  File "C:\python\lib\socket.py", line 704, in readinto
    return self._sock.recv_into(b)
urllib3.exceptions.ProtocolError: ('Connection aborted.', ConnectionResetError(10054, '远程主机强迫关闭了一个现有的连接。', None, 10054, None))
